Workbook

Sheet Summary 
A2: GreenCo Rating System (Version 3.0)
A3: Parameter | B3: Max Possible | C3: Preliminary Assessment Points | D3: Pending Points | E3: Preliminary Assessment 2018 | F3: Self / Preliminary Assessment (V3.0) | G3: Final Assessment / Actual Performance (V3.0)
A4: Energy Efficiency | B4: 150 | C4: ='[1]Creditwise Points'!E30 -> 50 | D4: ='[1]Creditwise Points'!F30 -> 55 | E4: ='[1]Creditwise Points'!G30 -> 117 | F4: =EE!E33 -> 0 | G4: =EE!F33 -> 0
A5: Water Conservation | B5: 100 | C5: ='[1]Creditwise Points'!E61 -> 40 | D5: ='[1]Creditwise Points'!F61 -> 20 | E5: ='[1]Creditwise Points'!G61 -> 72 | F5: =WC!E33 -> 0 | G5: =WC!F33 -> 0
A6: Renewable Energy | B6: 100 | C6: ='[1]Creditwise Points'!E90 -> 8 | D6: ='[1]Creditwise Points'!F90 -> 10 | E6: ='[1]Creditwise Points'!G90 -> 26 | F6: =RE!E14 -> 0 | G6: =RE!F14 -> 0
A7: Greenhouse Gas Emissions | B7: 100 | C7: ='[1]Creditwise Points'!E121 -> 50 | D7: ='[1]Creditwise Points'!F121 -> 15 | E7: ='[1]Creditwise Points'!G121 -> 71 | F7: =GHG!E45 -> 0 | G7: =GHG!F45 -> 0
A8: Waste Management | B8: 100 | C8: ='[1]Creditwise Points'!E157 -> 81 | D8: ='[1]Creditwise Points'!F157 -> 0 | E8: ='[1]Creditwise Points'!G157 -> 87 | F8: =WM!E38 -> 0 | G8: =WM!F38 -> 0
A9: Material Conservation, Recycling and Recyclability | B9: 100 | C9: ='[1]Creditwise Points'!E188 -> 45 | D9: ='[1]Creditwise Points'!F188 -> 15 | E9: ='[1]Creditwise Points'!G188 -> 56 | F9: =MCR!E34 -> 0 | G9: =MCR!F34 -> 0
A10: Green Supply Chain | B10: 100 | C10: ='[1]Creditwise Points'!E218 -> 75 | D10: ='[1]Creditwise Points'!F218 -> 10 | E10: ='[1]Creditwise Points'!G218 -> 64 | F10: =GSC!E31 -> 0 | G10: =GSC!F31 -> 0
A11: Product Stewardship & Life Cycle Assessment | B11: 125 | C11: ='[1]Creditwise Points'!E241 -> 52 | D11: ='[1]Creditwise Points'!F241 -> 10 | E11: ='[1]Creditwise Points'!G241 -> 60 | F11: =PSLCA!E29 -> 0 | G11: =PSLCA!F29 -> 0
A12: Innovation for Environment | B12: 50 | C12: ='[1]Creditwise Points'!E264 -> 40 | D12: ='[1]Creditwise Points'!F264 -> 10 | E12: ='[1]Creditwise Points'!G264 -> 65 | F12: =IE!E9 -> 0 | G12: =IE!F9 -> 0
A13: Green Infrastructure and Ecology | B13: 75 | C13: ='[1]Creditwise Points'!E279 -> 40 | D13: ='[1]Creditwise Points'!F279 -> 30 | E13: ='[1]Creditwise Points'!G279 -> 80 | F13: =GI!E34 -> 0 | G13: =GI!F34 -> 0
A14: Total | B14: =SUM(B4:B13) -> 1000 | C14: ='[1]Creditwise Points'!E281 -> 481 | D14: =SUM(D4:D13) -> 175 | E14: =SUM(E4:E13) -> 698 | F14: =SUM(F4:F13) -> 0 | G14: =SUM(G4:G13) -> 0

Sheet EE
A1: Energy Efficiency (150 Points)
A2: Credit Number | B2: Parameters | C2: Maximum Credit Points Allocated | E2: Self Assessment points | F2: Actual Performance | G2: Requirement
A3: Instruction | B3: Energy Mix and Energy Flow Diagram | G3: The unit has to provide - - Energy mix consisting of a pie chart showing the percentage and actual average consumption of thermal and electrical energy per month - Energy flow diagram showing thermal and electrical energy flow in the plant including various sources of energy
A4: EE Mandatory Requirement 1 | B4: Energy Policy | G4: An energy policy, duly signed by the head of the unit / facility or head of the organization, indicating - - Clearly defined objective and commitment to systematically reduce energy consumption and to improve energy efficiency - Targets for annual percentage reduction in energy consumption in short & long term
A5: EE Mandatory Requirement 2 | B5: Energy Management Cell & Energy Manager | G5: The energy management team should preferably - - Be a cross functional team (representatives from various departments such as operation, mechanical maintenance, electrical, instrumentation etc.) - Have clear responsibilities for improving energy efficiency in the plant - Be headed by full/part time energy manager directly reporting to the head of the plant
A6: EE Credit 1 | B6: Leadership and Strategy | C6: 20
A7: EE Credit 1.1 | B7: Target Setting | D7: 10
B8: Defined process of target setting | D8: 5 | G8: Highlight the methodology defined and used for setting the targets. The process of target setting should be well defined in the terms of logic behind setting of each targets.
B9: Target Setting | D9: 5 | G9: Set specific targets for reduction in specific energy consumption, separately for electrical energy and thermal energy, in addition to the overall target. Targets can be set in terms of internal or national or international benchmarking.
A10: EE Credit 1.2 | B10: Financial Resource Allocation - Spent Vs Allocated | D10: 5 | G10: The plant should commit upfront financial resource to minimize the gestation period between the identification of the energy efficiency improvement projects and their implementation. To facilitate speedy implementation of projects, upfront allocation of financial resource can be done. The plant team has to be empowered to make use of the allocated resources with specific guidelines on investment / ROI / payback period. 1. Provide approved budget for energy efficiency projects. This can be shown as a note sheet/letter of commitment from the top management or dedicated budget head in ERP systems 2. Details of the budget allocated vs budget spent on energy efficiency projects until now in the current and past two financial years.
A11: EE Credit 1.3 | B11: Monthly reviews pertaining to Energy Efficiency | D11: 5 | G11: The specific energy consumption must be presented and compared with previous month's performance and the respective target SEC. The meeting should be headed by the plant head. In addition to SEC, the progress of various projects identified under energy efficiency and the budget spent must be reviewed.
A12: EE Credit 2 | B12: Employee Involvement & Capacity Building | C12: 15
A13: EE Credit 2.1 | B13: Strategies adopted for awareness creation & employee involvement | D13: 5 | G13: Programs and initiatives taken by the plant team for employee involvement such as poster competitions, display of slogans, energy conservation week, incentives based on suggestion schemes arising out of kaizens, etc. should be carried out 1. Documentation of programs conducted for employee involvement and awareness creation for employees (specific to energy efficiency) 2. List of suggestions which were provided by the employees and the cost-benefit analysis of each suggestion 3. List of suggestions implemented, incentive/award/recognition given to the employees, etc.
A14: EE Credit 2.2 | B14: Training program, at least once in a year | D14: 5 | G14: Specific training programs should be conducted for employees to build capacities to contribute toward energy efficiency activities, which can include - - identification of training needs of employees and provide required training - impart advanced training to all the employees who are directly involved in identification & implementation of encon projects and members of encon cell - identification of best practices in energy efficiency, both cross sector and intra sector - industry visits to learn and understand best practices - encourage employees to attempt for energy auditor/energy manager or similar courses
A15: EE Credit 2.3 | B15: Energy scorecard | D15: 5 | G15: Energy Score card is a process of considering energy performance of the plant section as one of the criteria while appraising the performance of the plant personnel. This is applicable for plant personnel such as Energy managers, operation and maintenance engineers, operators where high manual intervention is required, who can make impact on energy efficiency of the plant.
A16: EE Credit 3 | B16: Energy Monitoring System | C16: 20
A17: EE Credit 3.1 | B17: Energy monitoring for equipment (Electrical & thermal) having >= 10% of total energy consumption | D17: 5 | G17: Install energy monitoring system and monitor both electrical & thermal energy consumption at the supply and user ends. Balance the energy supply with the consumption at the individual user ends and generate a daily report for analysis. The monitoring must be done daily in standard formats and the reasons for variations, if any, must be recorded. Highlight - 1. The percentage of overall average monthly energy consumption of all the major energy consumers (until 10% of the total energy consumption) 2. Daily monitoring sheets of energy consumer vs average energy consumption
B18: Energy monitoring for equipment (Electrical & thermal) having >= 5% of total energy consumption | D18: 5
A19: EE Credit 3.2 | B19: Daily variance analysis | D19: 5 | G19: Analyze the daily report and note any increase or decrease in energy consumption. Document the reasons for increase or decrease in energy consumption, for every +/- 10 % of variation from average daily consumption. For decrease, if there is no reason, then the new low will be taken as benchmark for target setting in the previous credit.
A20: EE Credit 3.3 | B20: Corrective Action Taken | D20: 5 | G20: The corrective action taken to address the variance in energy consumption should be documented. The status of projects and the benefits gained must also be presented
A21: EE Credit 4 | B21: Reduction in SEC in the past 3 years | C21: 50
B22: Reduction in SEC in the past 3 years | D22: 50 | G22: Highlight the specific energy consumption of the unit on a daily, monthly and yearly basis, for the past three years - Specific electrical energy consumption and specific thermal energy consumption data - Note: In case of new plants without three years' data, atleast two years data should be provided - Fixed or variable energy classification and monitoring for thermal and electrical energy - Projects implemented for reduction of SEC in the past 3 years along with the percentage impact of each project on reduction of SEC Note: Points will be allocated as per the percentage reduction achieved in the past three years, as per the table given below
B23: Note: In case, the unit has achieved its best performance figures (e.g. one of the lowest SEC at National level) and hence is not able to demonstrate high percentage reduction, the unit is eligible for maximum points under this credit
A24: EE Credit 5 | B24: Equipment Wise Efficiency Improvement | C24: 25
B25: Equipment wise efficiency monitoring and improvement | D25: 25 | G25: Performance evaluation of the energy intensive equipment need to be carried out and recorded. The equipment accounting for major consumption i.e. 80% of the total energy consumption of the plant needs to be considered for performance evaluation, supported with - - Consumption details of energy intensive equipment i.e. equipment consuming 80% of the total energy consumption in the plant - Performance evaluation of at least top five energy consuming equipment. e.g. furnace efficiency, kW/CFM of Air compressors, kW/TR of ACs etc.) to be periodically monitored. - Display of major equipment (having more than 5% of the plant’s consumption) (such as air compressors, furnaces etc.) must have a display of shift wise energy consumed and all operators on shift Note: The points will be allocated based on the deviation of the present efficiency of the equipment from the design efficiency or the best efficiency of the equipment available in the market
A26: EE Credit 6 | B26: Benchmarking with World Class Performance | C26: 20
A27: EE Credit 6.1 | B27: Process wise benchmark | G27: Process benchmarking data needs to be compared both internally and sector wise, or. Benchmarking audit for all major energy consuming equipment to be conducted
B28: Process of production is among top 10 best processes of production OR Conducted benchmarking audit for all major energy consuming equipment | D28: 5 | G28: Provide - Internal Benchmarking report and recommendations for all major energy consuming equipment or Process audit report and process benchmarking data denoting that the processes followed in the plant are among top 10 in the world
B29: At least 50% of the energy intensive equipment used in the factory is of best available market efficiency | D29: 5 | G29: Highlight the comparison of the equipment in the plant against the top 5 efficient equipment in the market from a verified source
A30: EE Credit 6.2 | B30: National/ International SEC benchmark | G30: The SEC of the plant must be among the top benchmarks at national and international level
B31: Among top 10 Units / Top 10% of the units at national level (National - Won any Energy Awards by premier institutions such as Govt of India, CII, IEA, BEE etc. : 2 points) | D31: 5 | G31: Provide - Comparison from a verified source denoting the SEC ranking of the plant among other plants in the sector, nationwide or Award certificate awarded for best energy performance or similar from a reputed body
B32: Among top 10 units / Top 10% of the units at international level | D32: 5 | G32: Highlight the comparison from a verified source denoting the global ranking in SEC of the plant among other plants in the sector
B33: Total | C33: =SUM(C5:C31) -> 150 | E33: =SUM(E5:E32) -> 0 | F33: =SUM(F5:F32) -> 0
A35: *Categorization of Sectors for Credit 4

Sheet WC
A1: Water Conservation (100 Points)
A2: Credit Number | B2: Parameters | C2: Maximum Credit Points Allocated | E2: Self Assessment points | F2: Actual Performance | G2: Requirement
A3: WC Mandatory Requirement 1 | B3: Water Policy | G3: The company should have a water policy signed by the head of the unit or organization. The policy statement should have a commitment from the top management on water conservation or reduction in water consumption over a period of time and the strategies for sustainable water management within the fence and beyond the fence. Note: The water policy can be a part of the sustainability policy or environmental policy
A4: WC Mandatory Requirement 2 | B4: Water Manager & Accountability | G4: The unit should have a dedicated water manager (part/full time) along with a cross functional team (part/full time) responsible for water management in the organization. Highlight the list of water management activities handled and projects implemented by the water manager and cross functional team.
A5: WC Credit 1 | B5: Leadership and Strategy | C5: 10
A6: WC Credit 1.1 | B6: Target setting & action plan | D6: 5 | G6: 1. Highlight specific targets for reduction in water consumption and regeneration or rain water harvesting. The targets should be based on specific water consumption and can be based on internal benchmarking. The process of target setting should be well defined in the terms of basis behind setting of each targets. 2. Action plan in terms of projects to achieve the targets should be mentioned, along with the anticipated benefits
A7: WC Credit 1.2 | B7: Monthly reviews on water conservation & management | D7: 5 | G7: The specific water consumption must be presented and compared with previous month's performance and the respective target SWC. The meeting should be headed by the plant head. In addition to SWC, the progress of various projects identified under water conservation and the budget spent must be reviewed.
A8: WC Credit 2 | B8: Employee Involvement & Capacity Building | C8: 10
A9: WC Credit 2.1 | B9: Awareness creation & employee involvement | D9: 5 | G9: Programs and initiatives taken by the plant team for employee involvement such as poster competitions, display of slogans, world water day, incentives based on suggestion schemes arising out of kaizens, etc. should be carried out 1. Documentation of programs conducted for employee involvement and awareness creation for employees (specific to water conservation) 2. List of suggestions which were provided by the employees and the cost-benefit analysis of each suggestion 3. List of suggestions implemented, incentive/award/recognition given to the employees, etc.
A10: WC Credit 2.2 | B10: Training & Capacity building | D10: 5 | G10: Specific training programs should be conducted for employees to build capacities to contribute toward water conservation activities, which can include - - identification of training needs of employees and provide required training - impart advanced training to all the employees who are directly involved in identification and implementation of water conservation projects - identification of best practices in water conservation, both cross sector and intra sector - industry visits to learn and understand best practices
A11: WC Credit 3 | B11: Water Balance Diagram | C11: 10
B12: Water balance diagram | D12: 10 | G12: A complete water balance diagram must be made tracing the water from inlet to outlet. The water flow for domestic and process use must be separately shown. The overall mix of process to domestic use must be given in a pie chart. The water balance diagram is should include the following 1. Water metering for critical locations accounting for more than 80% of fresh water consumption and waste water discharge with complete accounting a. Intake from sources – all sources to be covered b. Fresh Water Users – all individual users of consumption accounting for more than 10% of the total water consumption c. Monitoring of waste water generated, waste water recycled and waste water discharged as effluent 2. Collection and monitoring of water consumption on a monthly / yearly basis
A13: WC Credit 4 | B13: Reduction in Specific Fresh Water Consumption in Last 3 years | C13: 30
A14: WC Credit 4.1 | B14: Reduction in specific fresh water consumption in the last 3 years | D14: 25
B15: ≥ 5% reduction | D15: 5 | G15: Highlight the specific fresh water consumption of the unit on a daily, monthly and yearly basis, for the past three years - Specify process water and non-process water consumption data - Overall percentage of reduction calculated from the weighted averages of the reduction of domestic and process water consumption - Projects implemented for reduction of SWC in the past 3 years along with the percentage impact of each project on reduction of SWC Note: In case of new plants without three years' data, atleast two years data should be provided
B16: ≥ 10% reduction | D16: 10
B17: ≥ 15% reduction | D17: 15
B18: ≥ 20% reduction | D18: 20
B19: ≥ 25% reduction | D19: 25
B20: Note: In case, the unit has achieved its best performance figures (e.g. National best within the sector) and hence is not able to demonstrate high percentage reduction, the unit is eligible for maximum points under this credit
A21: WC Credit 4.2 | B21: Best practices in water conservation | D21: 5 | G21: Best practices that can be followed for water conservation are given for reference. Note that the list is not exhaustive and is presented only for reference. 1. Water Stress Study 2. Water-Efficient Landscaping & Irrigation practices 3. Use of Water Management Tools such as WATSCAN Allocation of points will be based on the efforts and the outcomes/benefits achieved by implementing best practices
A22: WC Credit 5 | B22: Rain Water Harvesting(RWH) in Roof and Non-Roof Areas | C22: 20
A23: WC Credit 5.1 | B23: Implementation of RWH structures | D23: 15 | G23: Rain water harvesting system should be implemented for roof and non-roof areas. The rain water potential shall be calculated based on the formula given in the reference guide / training. Points will be allocated based on the actual size of RWH storage pond/lake and also its recharge potential. Support with - - Design details of rain water harvesting systems - Details on the increase in water table - Details on the actual rain water captured on-surface pond Note: Effectiveness, maintenance/up-keep of the rain water harvesting system implemented will be verified on site
B24: ≥50% of the potential captured | D24: 5
B25: ≥65% of the potential captured | D25: 10
B26: ≥80% of the potential captured | D26: 15
A27: WC Credit 5.2 | B27: Substitution of process fresh water with harvested rain water | D27: 5 | G27: The harvested rain water has to be used in the process with minimum treatment Note: Recharge to ground wells, bore wells, etc. will not be awarded points
A28: WC Credit 6 | B28: Augmentation of ground water beyond fence | C28: 20
B29: At least 1 project implemented on augmentation of ground water | D29: 5 | G29: Highlight water conservation initiatives carried out beyond the fence, highlighting - Resource allocation for water conservation projects outside the fence - Details of the water augmentation projects - Documents to substantiate project completion and tangible and intangible benefits for the community and the company
B30: 1: 1 recharging/collection | D30: 10
B31: 1: 2 recharging/collection | D31: 15
B32: 1: 3 recharging/collection | D32: 20
B33: Total | C33: =SUM(C3:C32) -> 100 | E33: =SUM(E3:E32) -> 0 | F33: =SUM(F3:F32) -> 0

Sheet RE
A1: Renewable Energy (100 Points)
A2: Credit Number | B2: Parameters | C2: Maximum Credit Points Allocated | E2: Self Assessment points | F2: Actual Performance | G2: Requirement
A3: RE Mandatory Requirement | B3: Renewable Energy Policy | G3: A Renewable Energy policy duly signed by the head of the unit / facility or head of the organization, highlighting - - Clearly defined objective and commitment to systematically increase the renewable energy share of the unit - Targets for annual percentage reduction in energy consumption in the short and long term
A4: RE Credit 1 | B4: Leadership and Strategy | C4: 10
A5: RE Credit 1.1 | B5: Target setting - short term & long term targets and action plan | D5: 5 | G5: 1. Set specific targets for increase in renewable energy. The targets shall be in terms of absolute generation and specific energy generation. 2. Targets should be supported with projects identified for achieving the target. Projects should highlight its percentage contribution toward achieving the overall renewable energy substitution target
A6: RE Credit 1.2 | B6: Approved budget allocation for current & ensuing year and monitoring mechanism | D6: 5 | G6: The plant should commit upfront financial resource to minimize the gestation period between the identification of the renewable energy projects and their implementation. - Provide details of the budget allocated vs budget spent on renewable energy projects in the past three years
A7: RE Credit 2 | B7: On-site Renewable Energy Generation (Both Electrical & Thermal Energy) | C7: 25
B8: >=1% substitution | D8: 5 | G8: Indicate the percentage substitution achieved through renewable energy with respect to the overall energy consumption of the unit (electrical and thermal energy)
B9: >=2% substitution | D9: 10
B10: >=3% substitution | D10: 15
B11: >=4% substitution | D11: 20
B12: >=5% substitution | D12: 25
A13: RE Credit 3* | B13: Offsetting both Electrical & Thermal energy through Renewable Energy Sources | C13: 65 | G13: The renewable energy projects implemented by the company offsite can be considered. The other offsetting mechanisms such as green power procurement, REC purchase, investments can also be submitted, supported with the following, if applicable - 1. Agreement with the external power producers for power purchase 2. If the power is wheeled through state grid, the monthly power bill containing the RE units wheeled also needs to be submitted Refer the notes section below for allocation of points
B14: Total | C14: =SUM(C3:C13) -> 100 | E14: =SUM(E3:E13) -> 0 | F14: =SUM(F3:F13) -> 0
A15: Notes
A16: 1 | B16: In case the unit earns maximum points in RE Credit 1 & 2 , then the maximum number of points than can be earned in RE Credit 3 is only 65
A17: 2 | B17: In case the organization is unable to implement any onsite generation, it may choose to go up to 100 % offset though offsite RE generation, in which case the max points awarded will be 80 under RE Credit 3
A18: 3 | B18: If the company meets > 80% of its energy requirement through RE additional 5 points will be considered under innovation category
A19: 4 | B19: In case the onsite substitution exceeds 5 % the balance will be accounted in RE Credit 3
A20: 5 | B20: For Category 3 & 4, only electrical energy substitution will be considered.

Sheet GHG
A1: Green House Gases (100 Points)
A2: Credit Number | B2: Parameters | C2: Maximum Credit Points Allocated | E2: Self Assessment points | F2: Actual Performance | G2: Requirement
A3: GHG Mandatory Requirement | B3: GHG Emission Inventorization | G3: 1. Establish a system to monitor & account for the green house gas emission from various sources of operations annually based on internationally accepted protocols such as GHG protocol / ISO standards (ISO : 14064). 2. Scope 1 & Scope 2 emission are mandatory for the first year of GHG emission inventory and scope 3 emission are optional. However, it is compulsory to include all the 3 scopes of emission from the second year of Inventorization. - Scope 1: Direct GHG Emission: Direct GHG emission occur from sources that are owned or controlled by a company, for example, emission from combustion in owned or controlled boilers, furnaces, vehicles, etc.; - Scope 2: Electricity indirect GHG Emission: Scope 2 accounts for GHG emission from the generation of purchased electricity consumed by a company - Scope 3: Other indirect GHG Emission: Other indirect GHG Emission includes transportation emission due to movement of raw material & product, employee travel & product dispatch 3. Provide annual GHG inventory report containing the details of GHG emission under various scopes
A4: GHG Credit 1 | B4: GHG Emission Intensity Reduction Targets | C4: 10
A5: GHG Credit 1.1 | B5: Target setting - short term & long term targets | D5: 5 | G5: 1. Target setting for emission should be on the basis of emission intensity or absolute emission reduction from the baseline year 2. Short term targets - 1 – 2 years & long term targets - beyond 3 years 3. Highlight action plan in terms of emission mitigation opportunities to reduce the GHG emission levels, indicating analysis behind project identification and anticipated benefits (tangible and non-tangible) Approach & Methodology Based on the inventorization study, the present emission / emission intensity level, major emission source(s) / activities can be identified. Current emission intensity / level can then be compared with the national / international benchmark for similar unit / facility for setting the targets. There are various ways to identify the emission reduction options set as short term & long term targets. Few examples for emission reduction opportunities are: Scope1: Process / product improvement changes, technology up-gradation & altering the energy source Scope 2: Energy efficiency projects, renewable energy substitution etc. Scope 3: Fuel efficient vehicles, Logistics optimization & supplier emission reduction Prioritize emission mitigation opportunities by minimum investment and maximum reduction. All the minimum investment for emission reduction could be taken for achieving short term targets and higher investments as long term targets.
A6: GHG Credit 1.2 | B6: Action plan to achieve the targets | D6: 5
A7: GHG Credit 2 | B7: Employee Involvement & Capacity Building | C7: 10
A8: GHG Credit 2.1 | B8: Awareness creation & employee involvement | D8: 5 | G8: Awareness creation for all employees on green house gas emission can be organized through organizing contests, environmental week celebrations, screening movies on climate change, etc.
A9: GHG Credit 2.2 | B9: Organizing capacity building programmes to relevant employees once in a year to involve them in GHG emission activities | D9: 5 | G9: 1. Identify training needs of the employees 2. Conduct training program for all employees regarding climate change, GHG Inventorization, mitigation opportunities, etc. 3. Highlight the number of employees trained per year, content of the training programs, effectiveness of the programs, etc.
A10: GHG Credit 3 | B10: GHG Management Systems | C10: 10
A11: GHG Credit 3.1 | B11: GHG emission inventorization management | D11: 5 | G11: Implement a GHG management system for monitoring all three scopes of emission on a continuous basis. The GHG management system should consist of the following - 1. Systems to monitor, update & validate various scopes of emission, emission factors, boundary conditions of emission inventorization covering all three scopes of emission 2. Systems to monitor implementation of GHG emission reduction projects
A12: GHG Credit 3.2 | B12: Monitoring system for mitigation efforts | D12: 5
A13: GHG Credit 4 | B13: GHG Emission Intensity Reduction | C13: 25
A14: Option 1 | B14: For GHG intensive industries | D14: 25
B15: > 3% in last 3 years | D15: 5 | G15: 1. Indicate the reduction in GHG emission intensity of the unit in the last three years. The credit points are based on the percentage reduction in GHG intensity achieved in scope 1 and scope 2 GHG emission. 2. List of projects implemented that has facilitated the reduction in GHG emission intensity
B16: > 6% in last 3 years | D16: 10
B17: > 9% in last 3 years | D17: 15
B18: > 12% in last 3 years | D18: 20
B19: > 15% in last 3 years | D19: 25
A20: Option 2 | B20: For non-GHG intensive industries
B21: > 5% in last 3 years | D21: 5 | G21: 1. Indicate the reduction in GHG emission intensity of the unit in the last three years. The credit points are based on the percentage reduction in GHG intensity achieved in scope 1 and scope 2 GHG emission. 2. List of projects implemented that has facilitated the reduction in GHG emission intensity
B22: > 10% in last 3 years | D22: 10
B23: > 15% in last 3 years | D23: 15
B24: > 20% in last 3 years | D24: 20
B25: > 25% in last 3 years | D25: 25
A26: GHG Credit 5 | B26: Carbon Neutral Approach | C26: 25 | G26: 1. Implement carbon offset or carbon sequestration projects to offset the carbon emission 2. Inclusion of scope 3 emission is compulsory in GHG emission inventory while estimating the carbon neutrality of the unit
A27: Option 1 | B27: For GHG intensive industries | D27: 25
B28: Offset / sequestration ≥5% of total GHG emission | D28: 5 | G28: 1. List of projects implemented in carbon offset/sequestration areas and % offset/sequestration with respect to overall emission 2. Spreadsheet calculation demonstrating emission offset values
B29: Offset / sequestration ≥10% of total GHG emission | D29: 10
B30: Offset / sequestration ≥15% of total GHG emission | D30: 15
B31: Offset / sequestration ≥20% of total GHG emission | D31: 20
B32: Offset / sequestration ≥25% of total GHG emission | D32: 25
A33: Option 2 | B33: For non-GHG intensive industries
B34: Offset / sequestration ≥20% of total GHG emission | D34: 5 | G34: 1. Details of carbon offset/sequestration projects implemented through renewable power generation or green area development etc. 2.Spreadsheet calculation demonstrating emission offset values
B35: Offset / sequestration ≥40% of total GHG emission | D35: 10
B36: Offset / sequestration ≥60% of total GHG emission | D36: 15
B37: Offset / sequestration ≥80% of total GHG emission | D37: 20
B38: Offset / sequestration 100% of total GHG emission | D38: 25
A39: GHG Credit 6 | B39: Scope 3 emission inventorization | C39: 20
A40: GHG Credit 6.1 | B40: Scope 3 emission inventorization | D40: 5 | G40: Units have to inventorize for the following scope 3 emission categories to attain full points - - Material logistics (upstream & downstream) - Business travel - Waste disposal - Employee commute
...

Sheet WM
A1: Waste Management (Max:100 Points)
A2: Credit Number | B2: Parameters | C2: Maximum Credit Points Allocated | E2: Self Assessment points | F2: Actual Performance | G2: Requirement
A3: WM Mandatory Requirement 1 | B3: Waste Management Policy | G3: The waste management policy provides direction for all waste management activities in the company. A unit can have a policy exclusively for waste management or it can be a part of environment / sustainability policy that is signed by the Chief Executive of the company or unit head. It will form the basis upon which the unit can set its short and long term objectives and targets. This policy should be shared with all employees.
A4: WM Mandatory Requirement 2 | B4: Inventorization for Hazardous and Non-Hazardous Waste | G4: 1. All types of hazardous and non-hazardous wastes (inclusive of e-waste) should be quantified at each stage of waste management highlighting quantity and source of waste - generation - recycle/reuse - treatment - disposal 2. Total hazardous & non-hazardous waste disposed off in the last three years. Under disposal mechanism, explain if waste generated is recycled, reused after treatment, sold to third party or sent to landfill. Also explain the percentage of waste that is recycled or reused.
A5: WM Credit 1 | B5: Leadership & Strategy | C5: 10
A6: WM Credit 1.1 | B6: Short term & long term targets | D6: 5 | G6: The unit should have short and long term targets for reduction in waste disposal. Short term targets should be complied within 1-2 years period, medium term with 2 - 3 years, while long term targets can go beyond 3 years. The targets for reduction should be in terms of specific waste generation (waste / unit weight or volume of product) for all kind of wastes.
A7: WM Credit 1.2 | B7: Action plan and resource allocation | D7: 5 | G7: Top management should ensure availability of appropriate resources (financial, infrastructural, technological, manpower etc.) , for effective implementation of waste management system The performance of the waste management system should be reviewed on a monthly basis by Environment Management Cell & Unit head.
A8: WM Credit 2 | B8: Employee Involvement & Capacity Building | C8: 10
A9: WM Credit 2.1 | B9: Awareness creation and employee involvement | D9: 5 | G9: Programs and initiatives taken by the plant team for employee involvement such as poster competitions, display of slogans, world environment day celebrations, incentives based on suggestion schemes arising out of kaizens, etc. should be carried out 1. Documentation of programs conducted for employee involvement and awareness creation for employees (specific to waste management) 2. List of suggestions which were provided by the employees and the cost-benefit analysis of each suggestion 3. List of suggestions implemented, incentive/award/recognition given to the employees, etc.
A10: WM Credit 2.2 | B10: Training programs and capacity building | D10: 5 | G10: Specific training programs should be conducted for employees to build capacities to contribute toward waste management activities, which can include - - identification of training needs of employees and provide required training - impart training to all the employees over a span of two years - identification of best practices in waste management, both cross sector and intra sector - industry visits to learn and understand best practices
A11: WM Credit 3 | B11: Waste Management System | C11: 10
A12: WM Credit 3.1 | B12: Waste collection, segregation, internal transport & handling, storage and disposal mechanism | D12: 5 | G12: 1. The waste management systems such as SOP's, waste path and clearance frequencies shall be analyzed as per the requirements. The renewed SOP's and clearance frequencies shall be submitted 2. Similarly, the equipment for waste management such as bins, trucks, compactors, ETP/STP must be maintained as per maintenance schedules provided by the OEM. Provide details for maintenance of equipment for waste management as above 3. Waste management yard must have demarcated storage for hazardous waste and secondary containment for handling liquid spillage
A13: WM Credit 3.2 | B13: Audit of authorized recyclers | D13: 5 | G13: The recyclers to whom the waste is given for recycling shall be audited at least annually to confirm that the waste supplied from the client is processed in an environmentally-cautious manner. The audit reports of the recyclers shall be provided for analysis
A14: WM Credit 4 | B14: Solid Waste Management | C14: 25
A15: WM Credit 4.1 | B15: Hazardous Waste Management | D15: 10
B16: Option 1 - Reduction in hazardous waste disposal | G16: Highlight the specific waste disposal (hazardous waste) of the unit on a daily, monthly and yearly basis, for the past three years - Overall percentage of reduction of the hazardous waste disposal - Projects implemented for reduction of specific waste disposal in the past 3 years Reduction in specific waste generation from process / operation, through (a) change in process / operation / raw material, (b) increase in-house recycle/ reuse, (c ) yield improvement etc.
B17: ≥ 25% reduction in specific waste disposal (5 points)
B18: ≥ 40% reduction in specific waste disposal (10 points)
B19: Option 2 - Usage of waste as alternate fuel/raw material | G19: The unit can use the waste generated either as alternate fuel / raw material within the facility or by sending to other industries
B20: Usage of more than 50% of waste disposed as alternate fuel / raw material (5 points)
B21: Usage of more than 80% of waste disposed as alternate fuel / raw material (10 points)
A22: WM Credit 4.2 | B22: Non-Hazardous Waste Management | D22: 10
B23: ≥ 25% reduction in (absolute) waste generation in non-hazardous waste (5 points) | D23: 5 10 | G23: Highlight the waste generation (non-hazardous) of the unit on a daily, monthly and yearly basis, for the past three years - Overall percentage of reduction of the non-hazardous waste generation - Projects implemented for reduction of waste generation in the last three years through a) change in process / operation / raw material, b) increase in-house recycle/ reuse, c) yield improvement, etc.
B24: ≥ 40% reduction in (absolute) waste generation in non-hazardous waste (10 points)
A25: WM Credit 4.3 | B25: Zero waste to landfill | D25: 5 | G25: The organization should aim to achieve "Zero Waste Landfill" status for both hazardous and non hazardous waste. Proper evidence or internal audit report for the claim of Zero Waste to Landfill should be submitted. The unit management must also pay attention to the waste generated at the recycler's end.
A26: WM Credit 5 | B26: Liquid Waste Management | C26: 25
A27: WM Credit 5.1 | B27: Percentage reduction in process effluent discharge | D27: 15
B28: Reduction of process effluent generation | D28: 10 | G28: 1. Percentage reduction in process effluent discharge during the last three years 2. The unit should meet the conditions prescribed by SPCB or relevant local authorities
B29: ≥ 25% reduction (5 points)
B30: ≥ 40% reduction/zero effluent discharge (10 points)
B31: ≥ 25% recycling of process effluent in process applications | D31: 5 | G31: 1. Percentage of process effluent recycled back into process applications
A32: WM Credit 5.2 | B32: Percentage reduction in domestic / sewage waste generation | D32: 10
B33: ≥ 25% reduction of sewage waste generation / Zero liquid discharge | D33: 5 | G33: 1. Percentage reduction in sewage waste generation during the last three years 2. The unit should meet the conditions prescribed by SPCB or relevant local authorities
B34: 100% recycling of sewage waste for process / domestic application | D34: 5 | G34: 1. 100% recycling of sewage waste water has to be reused in process / domestic applications in the last three years 2. More weightage will be given for process requirement substitution in addition to gardening
A35: WM Credit 6 | B35: Gaseous Waste Management | C35: 20
A36: WM Credit 6.1* | B36: Air quality | D36: 15 | G36: Air emissions shall consist of 2 parameters - 1. Stack: All point sources with a stack to extract the pollutants 2. Ambient/Fugitive: The emissions coming out from processes as general or from other small equipment. Fugitive emissions are not extracted from stack. Hence, ambient air quality is measured. Note: Depending upon the category of the industry in the table below, the points for ambient and stack monitoring shall be arrived at
A37: WM Credit 6.2 | B37: Air pollution control technologies & best practices | D37: 5
B38: Total | C38: =SUM(C3:C37) -> 100 | E38: =SUM(E3:E37) -> 0 | F38: =SUM(F3:F37) -> 0
A41: *WM Credit 6.1 - Categorization of Industries for Air Quality | C41: Credit Distribution
C42: Ambient & workplace emission | D42: Stack | G42: Indicative list of Pollutants to be checked
...

Sheet MCR
A1: Material Conservation, Recycling & Recyclability (100 Points)
A2: Credit Number | B2: Parameters | C2: Maximum Credit Points Allocated | E2: Self Assessment points | F2: Actual Performance | G2: Requirement
A3: MCR Mandatory Requirement 1 | B3: Material Conservation & Recycling Policy | G3: The company has to have a Material Conservation and Recyclability policy /statement or it can be part of other implemented environmental policy approved by the Chief Executive of the company. The policy statement must, also, include a declaration of commitment from senior management to maximize the use of recycled materials in production and packaging or utilization with clearly specified annual targets. This policy information is to be transparent and has to be shared with the employees.
A4: MCR Credit 1 | B4: Leadership & Strategy | C4: 10
A5: MCR Credit 1.1 | B5: Short & long term targets | D5: 5 | G5: 1. Targets for raw materials, consumables and packaging material (In terms of yield improvement (raw material) as well as sustainable sourcing 2. Specific targets to be set for raw / packaging material substitution 3. Target for reducing specific consumption of major consumables 4. Process of target setting needs to be explained
A6: MCR Credit 1.2 | B6: Action plan and resource allocation | D6: 5 | G6: 1. List of projects in terms of action plan to achieve the targets 2. Allocation of resources, both in terms of manpower and finance 3. Review of resources allocated vs utilized, project status, fund utilization, etc.
A7: MCR Credit 2 | B7: Employee Involvement & Capacity Building | C7: 10
A8: MCR Credit 2.1 | B8: Awareness creation and employee involvement | D8: 5 | G8: 1. The unit should develop appropriate training and capacity building plan 2. Records of trainings (training calendar, feedback, effectiveness, up gradation of skill matrix etc.) to be maintained 3. Awareness creation on materials used in the plant and their recyclability's and impact on environment. Suggestion schemes and Kaizen's for material efficiency and substitution
A9: MCR Credit 2.2 | B9: Training programs and capacity building | D9: 5 | G9: 1. Training need identification 2. Number, types of capacity building and training programs conducted and its content
A10: MCR Credit 3 | B10: Systems | C10: 10
A11: MCR Credit 3.1 | B11: Framework for material conservation | D11: 5 | G11: 1. Provide overall material balance for the process / product(s) manufactured. A pie chart indicating the representative percentages of annual consumption of raw material, consumables, packaging shall be provided 2. Type of system used to monitor various raw material consumption, recycling & reusing of materials (Material includes – raw material, consumables, spares and packaging materials) 3. Tools , techniques & Technologies used for material reduction, reuse & recycling etc.
A12: MCR Credit 3.2 | B12: Systematic monitoring plans | D12: 5 | G12: Describe the monitoring system for raw material consumption and yield improvement, its review mechanism and substantiate with cases
A13: MCR Credit 4 | B13: Raw Material Conservation | C13: 35
A14: MCR Credit 4.1 | B14: Percentage reduction in specific raw material consumption | D14: 20 | G14: 1. Reduction in specific raw material consumption in the last three years (Provide the absolute and specific numbers to arrive at a weighted average) 2. List of projects implemented in achieving the reduction
B15: ≥3% reduction in raw material consumption (5 points)
B16: ≥9% reduction in raw material consumption (10 points)
B17: ≥12% reduction in raw material consumption (15 points)
B18: ≥15% reduction in raw material consumption (20 points)
A19: MCR Credit 4.2 | B19: Replacement of raw materials by recycled material / waste or equivalent | D19: 15 | G19: Use of Recycled material/waste or equivalent in the last three years (only raw material and not including fuel). The company should substitute the virgin material consumption in their process / product, through recycled / alternate / waste material or equivalent. Moreover, the focus should be usage for more eco-friendly, recyclable, renewable materials, rather than non-renewable ones
B20: ≥15% usage of recycled / waste material or equivalent (5 points)
B21: ≥20% usage of recycled / waste material or equivalent (10 points)
B22: ≥25% usage of recycled / waste material or equivalent (15 points)
A23: MCR Credit 5 | B23: Specific Reduction in Consumables | C23: 15
B24: ≥5% reduction in consumables (5 points) | G24: 1. The list of major consumables and its specific intensity consumption to be provided 2. The company should optimize / reduce specific consumption of major consumables (lube oil, grease, coolants, chemicals & etc.), office stationary items, through in-house recycle, reuse etc.
B25: ≥10% reduction in consumables (10 points)
B26: ≥15% reduction in consumables (15 points)
A27: MCR Credit 6 | B27: Management of Packaging Material | C27: 20
A28: MCR Credit 6.1 | B28: Reduction in packaging material | D28: 10 | G28: 1. List of different packaging materials used in the plant 2. Initiatives taken by the company to reduce consumption of packaging material 3. Percentage reduction in packaging material used
B29: ≥15% reduction in packaging material (5 points)
B30: ≥30% reduction in packaging material (10 points)
A31: MCR Credit 6.2 | B31: Recycled content in packaging material | D31: 10 | G31: 1. Initiatives taken by the company to increase the recycled content of packaging material 2. Percentage recycled content in various packing material 3. Test certificate for recycled content in the packaging material
B32: ≥20% recycled content in packaging material (5 points)
B33: ≥40% recycled content in packaging material (10 points)
B34: Total | C34: =SUM(C4:C31) -> 100 | E34: =SUM(E4:E33) -> 0 | F34: =SUM(F4:F33) -> 0

Sheet GSC
A1: Green Supply Chain (100 Points)
A2: Credit Number | B2: Parameters | C2: Maximum Credit Points Allocated | E2: Self Assessment points | F2: Actual Performance | G2: Requirement
A3: GSC Mandatory Requirement 1 | B3: Identification of Critical Suppliers / Vendors | G3: 1. List all of vendors / suppliers / associates, etc. 2. Describe the method of identification of Critical Suppliers/ Vendors for Green Supply chain program. The selection may be based on Environmental impact, criticality, geography, SME status etc. 3. Addition of vendors / associates / service providers involved in waste management and recycling (e.g.: e-waste recycler, hazardous waste management company, etc.) under critical suppliers / vendors
A4: GSC Mandatory Requirement 2 | B4: Green Supply Chain Cell / Team | G4: 1. Presence of a green supply chain cell / team, a cross functional one, including representatives from production, maintenance, quality, EHS, etc. in addition to purchase / procurement, training / HR and logistic team and/or third party experts 2. The green supply chain cell should have clearly defined roles and responsibilities in this regard
A5: GSC Credit 1 | B5: Leadership and Strategy | C5: 10
A6: GSC Credit 1.1 | B6: Green supply chain commitment | D6: 5 | G6: The commitment of the top management toward greening the supply chain should be demonstrated. For instance, the availability of a green supply chain policy which will serve as a guidance document to improve the efficiency of the supply chain. The green supply chain policy can be an exclusive policy or can be present as a part of the existing larger policies.
A7: GSC Credit 1.2 | B7: Targets, action plan and resource allocation | D7: 5 | G7: 1. Highlight the targets set by the unit in all the areas of green supply chain. E.g.: awareness creation, logistics, procurement, etc. Targets to be highlighted in terms of short term - <1 year, medium term 1-2 years, and long term targets >3 years 2. Action plan to meet the short, medium and long term targets 3. Resources allocated for executing the targets and action plan including financial resources, man power, infrastructure and / or technology
A8: GSC Credit 2 | B8: Education and Awareness Creation | C8: 10
A9: GSC Credit 2.1 | B9: Awareness creation for the suppliers, vendors, associates, etc. | D9: 5 | G9: Highlight the education and awareness programs conducted for vendors / suppliers / distribution channels / logistics service providers, etc. for improving their efficiency 1. Cluster approach / vendor development programs, etc. 2. Targeted trainings to the suppliers 3. Trainings conducted in annual vendor meet 4. Online forum/blogs for suppliers 5. Sharing education material via email, etc.
A10: GSC Credit 2.2 | B10: Training program for suppliers, vendors, associates, etc. | D10: 5 | G10: Highlight the various training programs carried out for suppliers, vendors, associates, etc. The organization should have a system to - - create platforms to engage and train suppliers / vendors - develop programs such as cluster activities, vendor development programs, etc. Along with the above-mentioned details, provide more information on content of the trainings, frequency of trainings and impact of the trainings
A11: GSC Credit 3 | B11: Resource Conservation through Supply Chain Management Systems | C11: 5 | G11: 1. Describe the systems employed for supply chain management (e.g.: software tools for supply chain transactions , customer requirement processing, purchase order processing, etc.) 2. How does the system measure the reduction in resource intensity in the supply chain on regular basis? 3. How does the system monitor specific requirements with respect to - - procurement - supplier packaging - logistics - supplier audits, etc.
A12: GSC Credit 4 | B12: Suppliers and Vendors Management | C12: 40
A13: GSC Credit 4.1 | B13: Baseline development for all critical suppliers and vendors | D13: 10 | G13: Baseline performance of the critical suppliers in the relevant areas (e.g.: energy, water, waste, material, carbon, toxicity, etc.) should be framed along with a clear timeline for implementation Guideline to frame a baseline - • Choose and report a base year for which verifiable performance numbers are available (Specify reasons for choosing that particular year) • A single year can be chosen as a base year • Also, an average of annual performance figures over several consecutive years can be chosen as the baseline figure (A multi-year average may help smooth out unusual fluctuations that would make a single year’s data unrepresentative) • Recalculate the baseline, if there are – - errors in accounting - changes in suppliers / vendors whose numbers were used in baseline calculation • The base line has to be used as a basis for setting and tracking progress towards target
A14: GSC Credit 4.2 | B14: % improvement in performance over the set baseline | D14: 15 | G14: % improvement in performance of the critical suppliers with respect to the baseline framed should be monitored and points will be allocated based on the % improvement
B15: 5% improvement | D15: 5
B16: 10% improvement | D16: 10
B17: 15% improvement | D17: 15
A18: GSC Credit 4.3 | B18: Supplier / vendor audits for >90% of the critical suppliers / vendors | D18: 5 | G18: 1. Copy of the supplier audit questionnaire 2. Number of supplier audits carried out and the frequency of audits 3. Sample audit reports
A19: GSC Credit 4.4 | B19: Recognition programs of the critical suppliers / vendors | D19: 5 | G19: The company should conduct supplier recognition programs as a planned event, by considering the following; - evaluation criteria and questionnaire - awards and recognition programs
A20: GSC Credit 4.5 | B20: GreenCo rated SMEs | D20: 5 | G20: 1. Units while selecting new vendors or suppliers should ensure they are rated as per GreenCo / GreenCo SMEs guidelines or equivalent 2. Units should encourage and support existing suppliers and vendors to implement the GreenCo rating system. Maximum points will be allocated if atleast 10% of the critical suppliers are GreenCo rated.
A21: GSC Credit 5 | B21: Green Procurement | C21: 15
A22: GSC Credit 5.1 | B22: Implementation of green procurement guidelines | D22: 10 | G22: 1. Copy of the green procurement guidelines. Guidelines should address the following - a) Raw Material, (b) Consumables, (C ) Packaging Material, (D) Building Materials, (E ) Capital items / fixtures, (F) Housekeeping Chemicals, (G) Paints etc. 2. Describe the % of procurement for every category based on the green procurement guidelines. Support with documents, etc.
A23: GSC Credit 5.2 | B23: Purchase of green certified products or materials | D23: 5 | G23: Describe with supporting the documents the purchase of green certified products or materials such as BEE star rated appliances, CII-GreenPro certified materials, GS-37 or equivalent standard certified house-keeping chemicals, FSC certified raw / packaging materials, RoHS complied products / materials etc.
A24: GSC Credit 6 | B24: Supply chain efficiency improvement | C24: 20
A25: GSC Credit 6.1 | B25: Packaging | D25: 10 | G25: Improvement in packaging efficiency of the materials received from the supplier-delivered products / goods. Points will be given for the efforts taken to identify alternate materials that will also lead to reduction in packaging material. (Since the credit requirement varies from case to case, the points distribution for this credit can be kept variable) The credit is not applicable for the company's product
B26: Reduction in >15% of the incoming packaging | D26: 5
B27: Reduction in >30% of the incoming packaging | D27: 5
A28: GSC Credit 6.2 | B28: Logistics | D28: 10 | G28: Note: Transport emissions indicate upstream and downstream emissions Initiatives taken to enhance logistics efficiency - development of local vendors / local purchase - influencing vendors to set up local manufacturing facility / vendor park development - initiatives taken to minimize GHG impacts in supply chain (Milk Run System, Route Optimization, Bulk transportation, mode of transportation, Utilization of energy efficient fleets / transportation mode, Application of tools / technologies to track the logistics movement, etc.) Note: In case the vendor park is already developed, as a part of the initial planning, the % reduction will be appropriately apportioned
B29: Reduction in >10% of the GHG emissions from transportation | D29: 5
B30: Reduction in >20% of the GHG emissions from transportation | D30: 5
B31: Total | C31: =SUM(C5:C28) -> 100 | E31: =SUM(E5:E30) -> 0 | F31: =SUM(F5:F30) -> 0

Sheet PSLCA
A1: Product Stewardship & Life Cycle Aspects (125 points)
A2: Credit Number | B2: Parameters | C2: Maximum Credit Points Allocated | E2: Self Assessment points | F2: Actual Performance | G2: Requirement
A3: PSLCA Credit 1 | B3: Leadership and Strategy | C3: 10
A4: PSLCA Credit 1.1 | B4: Strategy & commitment | D4: 5 | G4: The top management can demonstrate their commitment toward product stewardship and life cycle thinking using the following approach - 1. Use of LCA as a tool for product design / sustainability 2. Commitment to LCA by adding its methodology to any of the policies concerning environment 3. Strategy for incorporation of Safety, Health and Environmental aspects at the design phase of their product(s) (e.g. DFE, Eco-design etc.), as well as ensure the quality of the product(s) (as its intended for) till its lifetime / shelf-life (to be defined by the company) 4. Strategy for managing the end-of-life of the product(s) 5. Strategy to communicate to the customers about the importance of their product(s), including the use of product efficiently, safely and with the least environmental impact as well as scientific disposal at the end of life 6. Strategy to influence customer / consumer behavior of proper handling, storage, usage, transportation and scientific disposal (wherever applicable) of product(s), etc.
A6: PSLCA Credit 1.2 | B6: Targets and action plan | D6: 5 | G6: Company should develop the target as well as time-based action plan for - 1. Conducting LCA study for their product(s) within a given time frame vis-a-vis an action plan for conducting the LCA study (Objective of study, Boundary of study, data requirements, literature review, resource allocation, etc.) 2. Action plan for reducing the negative impact of the product/services, minimize/eliminate the hazardous/toxic substance(s), develop Environmental Product Declaration (EPD) for the product(s), etc.
A7: PSLCA Credit 2 | B7: Life Cycle Aspects | C7: 25
A8: PSLCA Credit 2.1 | B8: Internal life cycle assessment (LCA) study | D8: 10 | G8: Conduct Life Cycle Assessment study for their product(s), by internal technical team, considering one of the following product boundaries - a. Gate to Gate b. Cradle to Gate c. Cradle to cradle To conduct internal LCA study, companies should (a) develop the employees' capability, (b) can use openly available software or external software tools such as Gabi, Simapro with a clear scope & boundary
A9: PSLCA Credit 2.2 | B9: External LCA study | D9: 10 | G9: Companies can use internally trained experts or engage external LCA experts to conduct the LCA study using external verified software tools such as Gabi, Simapro, etc.
A10: PSLCA Credit 2.3 | B10: Peer review of external LCA study | D10: 5 | G10: LCA study shall be reviewed by a third party based on the ISO 14040 &14044 standards. The study report must be used in some projects relating to improvement of bottom line and/or environmental footprint of the company
A11: PSLCA Credit 3 | B11: Product Responsibility Management | C11: 20
A12: PSLCA Credit 3.1 | B12: Ensure product quality and conduct environment risk assessment of the product during transport, handling, storage, use and disposal phase | D12: 5 | G12: 1. Companies should develop system to ensure that the quality of the products and services is being maintained until its final delivery to the end user. Provide the details of the quality management systems implemented by the company for reducing waste / rejection during transport, handling, storage, use and disposal phase 2. Companies should develop a system for evaluating the environmental risk associated during transport, handling, storage, use and disposal of the product 3. Documentation of all the aspects related to Quality, Safety, Health and Environment faced by the customer during the usage and at the end of life of the product
A13: PSLCA Credit 3.2 | B13: System to capture customer feedback | D13: 5 | G13: 1.Establish system to capture customer feedback 2. Brief on design changes or process changes as a result of customer feedback to be documented 3. In case of any complaints on the containers/content of the product - - the product has to be withdrawn from the supply chain - failure analysis has to be done - comparison with initial design/pilot test reports has to be done (E.g.: Destructive testing and non destructive testing parameters) so that recurrence of failure can be avoided - Detailed procedures on this to be made available
A14: PSLCA Credit 3.3 | B14: Environmental impact reduction based on LCA (Carbon/Material/Water/Toxicity) | D14: 10 | G14: Based upon the LCA study, companies should identify - potential economic, social, environment risks & opportunities at each stage of the life cycle for products - manage/reduce the environmental impacts by a significant amount over a specified timeline. The reduction can be in terms of Acidification, Eutrophication, Global warming potential, Ozone Depletion, Photochemical smog. Note: Companies should submit the details of projects identified / implemented / under implementation, for reduction in environmental impacts of any of the impact categories
A15: PSLCA Credit 4 | B15: Communicating with Stakeholders | C15: 20
